2023-09-12 18:57:44 [ERROR]: Task exception was never retrieved
future: <Task finished name='Task-6' coro=<WebcastPushConnection.__websocket_connect() done, defined at /home/rom3/.local/lib/python3.10/site-packages/TikTokLive/client/base.py:174> exception=AttributeError("'list' object has no attribute 'manually_closed'") created at /home/rom3/.local/lib/python3.10/site-packages/TikTokLive/client/base.py:327>
source_traceback: Object created at (most recent call last):
  File "/home/rom3/skribbletok/src/dispatcher.py", line 140, in <module>
    asyncio.run(dispatch.run(), debug=True)
  File "/usr/lib/python3.10/asyncio/runners.py", line 44, in run
    return loop.run_until_complete(main)
  File "/usr/lib/python3.10/asyncio/base_events.py", line 633, in run_until_complete
    self.run_forever()
  File "/usr/lib/python3.10/asyncio/base_events.py", line 600, in run_forever
    self._run_once()
  File "/usr/lib/python3.10/asyncio/base_events.py", line 1888, in _run_once
    handle._run()
  File "/usr/lib/python3.10/asyncio/events.py", line 80, in _run
    self._context.run(self._callback, *self._args)
  File "/home/rom3/skribbletok/src/tools/pulsar.py", line 60, in run
    await self.execute()
  File "/home/rom3/skribbletok/src/tools/pulsar.py", line 49, in execute
    await self.loop()
  File "/home/rom3/skribbletok/src/dispatcher.py", line 63, in loop
    await self.client._start()
  File "/home/rom3/.local/lib/python3.10/site-packages/TikTokLive/client/base.py", line 368, in _start
    await self.start()
  File "/home/rom3/.local/lib/python3.10/site-packages/TikTokLive/client/base.py", line 359, in start
    await self._connect()
  File "/home/rom3/.local/lib/python3.10/site-packages/TikTokLive/client/base.py", line 327, in _connect
    self._ws_connection_task = self.loop.create_task(self.__websocket_connect(webcast_response))
Traceback (most recent call last):
  File "/home/rom3/.local/lib/python3.10/site-packages/TikTokLive/client/base.py", line 220, in __websocket_connect
    if websocket.manually_closed:
AttributeError: 'list' object has no attribute 'manually_closed'
2023-09-13 01:40:08 [ERROR]: Task was destroyed but it is pending!
task: <Task pending name='Task-6' coro=<Hub.graceful_exit() running at /home/rom3/skribbletok/src/tools/pulsar.py:108>>
2023-09-13 01:44:23 [ERROR]: Task was destroyed but it is pending!
task: <Task pending name='Task-6' coro=<Hub.graceful_exit() running at /home/rom3/skribbletok/src/tools/pulsar.py:108>>
2023-09-13 01:47:18 [ERROR]: Task was destroyed but it is pending!
task: <Task pending name='Task-6' coro=<Hub.graceful_exit() running at /home/rom3/skribbletok/src/tools/pulsar.py:108>>
2023-09-13 01:51:51 [ERROR]: Task was destroyed but it is pending!
task: <Task pending name='Task-6' coro=<Hub.graceful_exit() running at /home/rom3/skribbletok/src/tools/pulsar.py:108>>
2023-09-13 02:00:20 [ERROR]: Task was destroyed but it is pending!
task: <Task pending name='Task-6' coro=<Hub.graceful_exit() running at /home/rom3/skribbletok/src/tools/pulsar.py:108>>
2023-09-13 02:00:55 [ERROR]: Task was destroyed but it is pending!
task: <Task pending name='Task-6' coro=<Hub.graceful_exit() running at /home/rom3/skribbletok/src/tools/pulsar.py:108>>
2023-09-13 02:03:21 [ERROR]: Task was destroyed but it is pending!
task: <Task pending name='Task-6' coro=<Hub.graceful_exit() running at /home/rom3/skribbletok/src/tools/pulsar.py:108>>
2023-09-13 02:10:01 [ERROR]: Task was destroyed but it is pending!
task: <Task pending name='Task-7' coro=<Hub.graceful_exit() running at /home/rom3/skribbletok/src/tools/pulsar.py:108>>
2023-09-13 02:10:47 [ERROR]: Task was destroyed but it is pending!
task: <Task pending name='Task-7' coro=<Hub.graceful_exit() running at /home/rom3/skribbletok/src/tools/pulsar.py:108>>
2023-09-13 02:18:55 [ERROR]: Task was destroyed but it is pending!
task: <Task pending name='Task-7' coro=<Hub.graceful_exit() running at /home/rom3/skribbletok/src/tools/pulsar.py:108>>
2023-09-13 02:19:35 [ERROR]: Task was destroyed but it is pending!
task: <Task pending name='Task-7' coro=<Hub.graceful_exit() running at /home/rom3/skribbletok/src/tools/pulsar.py:108>>
2023-09-13 02:20:16 [ERROR]: Task was destroyed but it is pending!
task: <Task pending name='Task-7' coro=<Hub.graceful_exit() running at /home/rom3/skribbletok/src/tools/pulsar.py:108>>
2023-09-13 02:21:11 [ERROR]: Task was destroyed but it is pending!
task: <Task pending name='Task-7' coro=<Hub.graceful_exit() running at /home/rom3/skribbletok/src/tools/pulsar.py:108>>
2023-09-13 02:21:11 [ERROR]: exception calling callback for <Future at 0x7f31977f7460 state=finished returned NoneType>
Traceback (most recent call last):
  File "/usr/lib/python3.10/concurrent/futures/_base.py", line 342, in _invoke_callbacks
    callback(self)
  File "/usr/lib/python3.10/asyncio/futures.py", line 399, in _call_set_state
    dest_loop.call_soon_threadsafe(_set_state, destination, source)
  File "/usr/lib/python3.10/asyncio/base_events.py", line 795, in call_soon_threadsafe
    self._check_closed()
  File "/usr/lib/python3.10/asyncio/base_events.py", line 515, in _check_closed
    raise RuntimeError('Event loop is closed')
RuntimeError: Event loop is closed
2023-09-13 02:21:21 [ERROR]: Task was destroyed but it is pending!
task: <Task pending name='Task-7' coro=<Hub.graceful_exit() running at /home/rom3/skribbletok/src/tools/pulsar.py:108>>
2023-09-13 02:22:36 [ERROR]: Task was destroyed but it is pending!
task: <Task pending name='Task-7' coro=<Hub.graceful_exit() running at /home/rom3/skribbletok/src/tools/pulsar.py:108>>
2023-09-13 02:38:16 [ERROR]: Task was destroyed but it is pending!
task: <Task pending name='Task-7' coro=<Hub.graceful_exit() running at /home/rom3/skribbletok/src/tools/pulsar.py:108>>
2023-09-13 02:38:16 [ERROR]: exception calling callback for <Future at 0x7f5c97d40e80 state=finished returned NoneType>
Traceback (most recent call last):
  File "/usr/lib/python3.10/concurrent/futures/_base.py", line 342, in _invoke_callbacks
    callback(self)
  File "/usr/lib/python3.10/asyncio/futures.py", line 399, in _call_set_state
    dest_loop.call_soon_threadsafe(_set_state, destination, source)
  File "/usr/lib/python3.10/asyncio/base_events.py", line 795, in call_soon_threadsafe
    self._check_closed()
  File "/usr/lib/python3.10/asyncio/base_events.py", line 515, in _check_closed
    raise RuntimeError('Event loop is closed')
RuntimeError: Event loop is closed
2023-09-13 02:41:16 [ERROR]: Task was destroyed but it is pending!
task: <Task pending name='Task-7' coro=<Hub.graceful_exit() running at /home/rom3/skribbletok/src/tools/pulsar.py:108>>
2023-09-13 02:42:52 [ERROR]: Task was destroyed but it is pending!
task: <Task pending name='Task-7' coro=<Hub.graceful_exit() running at /home/rom3/skribbletok/src/tools/pulsar.py:108>>
2023-09-13 02:42:52 [ERROR]: exception calling callback for <Future at 0x7fa92f574610 state=finished returned NoneType>
Traceback (most recent call last):
  File "/usr/lib/python3.10/concurrent/futures/_base.py", line 342, in _invoke_callbacks
    callback(self)
  File "/usr/lib/python3.10/asyncio/futures.py", line 399, in _call_set_state
    dest_loop.call_soon_threadsafe(_set_state, destination, source)
  File "/usr/lib/python3.10/asyncio/base_events.py", line 795, in call_soon_threadsafe
    self._check_closed()
  File "/usr/lib/python3.10/asyncio/base_events.py", line 515, in _check_closed
    raise RuntimeError('Event loop is closed')
RuntimeError: Event loop is closed
2023-09-13 04:20:08 [ERROR]: Task was destroyed but it is pending!
task: <Task pending name='Task-7' coro=<Hub.graceful_exit() running at /home/rom3/skribbletok/src/tools/pulsar.py:108>>
2023-09-13 04:20:08 [ERROR]: exception calling callback for <Future at 0x7fddd0e9d330 state=finished returned NoneType>
Traceback (most recent call last):
  File "/usr/lib/python3.10/concurrent/futures/_base.py", line 342, in _invoke_callbacks
    callback(self)
  File "/usr/lib/python3.10/asyncio/futures.py", line 399, in _call_set_state
    dest_loop.call_soon_threadsafe(_set_state, destination, source)
  File "/usr/lib/python3.10/asyncio/base_events.py", line 795, in call_soon_threadsafe
    self._check_closed()
  File "/usr/lib/python3.10/asyncio/base_events.py", line 515, in _check_closed
    raise RuntimeError('Event loop is closed')
RuntimeError: Event loop is closed
2023-09-13 04:21:15 [ERROR]: Task was destroyed but it is pending!
task: <Task pending name='Task-7' coro=<Hub.graceful_exit() running at /home/rom3/skribbletok/src/tools/pulsar.py:108>>
2023-09-13 04:21:23 [ERROR]: Task was destroyed but it is pending!
task: <Task pending name='Task-7' coro=<Hub.graceful_exit() running at /home/rom3/skribbletok/src/tools/pulsar.py:108>>
2023-09-13 04:21:31 [ERROR]: Task was destroyed but it is pending!
task: <Task pending name='Task-7' coro=<Hub.graceful_exit() running at /home/rom3/skribbletok/src/tools/pulsar.py:108>>
2023-09-15 10:50:30 [ERROR]: An error occurred: connection already closed
2023-09-15 10:50:32 [ERROR]: An error occurred: connection already closed
2023-09-15 10:50:34 [ERROR]: An error occurred: connection already closed
2023-09-15 10:50:36 [ERROR]: An error occurred: connection already closed
2023-09-15 10:50:37 [ERROR]: An error occurred: connection already closed
2023-09-15 10:50:40 [ERROR]: An error occurred: connection already closed
2023-09-15 10:50:41 [ERROR]: An error occurred: connection already closed
2023-09-15 10:50:44 [ERROR]: An error occurred: connection already closed
2023-09-15 10:50:46 [ERROR]: An error occurred: connection already closed
2023-09-15 10:50:48 [ERROR]: An error occurred: connection already closed
2023-09-15 10:50:50 [ERROR]: An error occurred: connection already closed
2023-09-15 10:50:52 [ERROR]: An error occurred: connection already closed
2023-09-15 10:50:54 [ERROR]: An error occurred: connection already closed
2023-09-15 10:50:56 [ERROR]: An error occurred: connection already closed
2023-09-15 10:50:58 [ERROR]: An error occurred: connection already closed
2023-09-15 10:51:00 [ERROR]: An error occurred: connection already closed
2023-09-15 10:51:03 [ERROR]: An error occurred: connection already closed
2023-09-15 10:51:04 [ERROR]: An error occurred: connection already closed
2023-09-15 10:51:06 [ERROR]: An error occurred: connection already closed
2023-09-15 10:51:08 [ERROR]: An error occurred: connection already closed
2023-09-15 10:51:10 [ERROR]: An error occurred: connection already closed
2023-09-15 10:51:12 [ERROR]: An error occurred: connection already closed
2023-09-15 10:51:14 [ERROR]: An error occurred: connection already closed
2023-09-15 10:51:16 [ERROR]: An error occurred: connection already closed
2023-09-15 10:51:18 [ERROR]: An error occurred: connection already closed
2023-09-15 10:51:20 [ERROR]: An error occurred: connection already closed
2023-09-15 10:51:22 [ERROR]: An error occurred: connection already closed
2023-09-15 10:51:24 [ERROR]: An error occurred: connection already closed
2023-09-15 10:51:26 [ERROR]: An error occurred: connection already closed
2023-09-15 10:51:28 [ERROR]: An error occurred: connection already closed
2023-09-15 10:51:30 [ERROR]: An error occurred: connection already closed
2023-09-15 10:51:32 [ERROR]: An error occurred: connection already closed
2023-09-15 10:51:34 [ERROR]: An error occurred: connection already closed
2023-09-15 10:51:36 [ERROR]: An error occurred: connection already closed
2023-09-15 10:51:38 [ERROR]: An error occurred: connection already closed
2023-09-15 10:51:40 [ERROR]: An error occurred: connection already closed
2023-09-15 10:51:42 [ERROR]: An error occurred: connection already closed
2023-09-15 10:51:44 [ERROR]: An error occurred: connection already closed
2023-09-15 10:51:46 [ERROR]: An error occurred: connection already closed
2023-09-15 10:51:48 [ERROR]: An error occurred: connection already closed
2023-09-15 10:51:50 [ERROR]: An error occurred: connection already closed
2023-09-15 10:51:52 [ERROR]: An error occurred: connection already closed
2023-09-15 10:51:54 [ERROR]: An error occurred: connection already closed
2023-09-15 10:51:56 [ERROR]: An error occurred: connection already closed
2023-09-15 10:51:58 [ERROR]: An error occurred: connection already closed
2023-09-15 10:52:00 [ERROR]: An error occurred: connection already closed
2023-09-15 10:52:02 [ERROR]: An error occurred: connection already closed
2023-09-15 10:52:04 [ERROR]: An error occurred: connection already closed
2023-09-15 10:52:06 [ERROR]: An error occurred: connection already closed
2023-09-15 10:52:08 [ERROR]: An error occurred: connection already closed
2023-09-15 10:52:10 [ERROR]: An error occurred: connection already closed
2023-09-15 10:52:12 [ERROR]: An error occurred: connection already closed
2023-09-15 10:52:14 [ERROR]: An error occurred: connection already closed
2023-09-15 10:52:16 [ERROR]: An error occurred: connection already closed
2023-09-15 10:52:18 [ERROR]: An error occurred: connection already closed
2023-09-15 10:52:20 [ERROR]: An error occurred: connection already closed
2023-09-15 10:52:21 [ERROR]: An error occurred: connection already closed
2023-09-15 10:52:24 [ERROR]: An error occurred: connection already closed
2023-09-15 10:52:26 [ERROR]: An error occurred: connection already closed
2023-09-15 10:52:28 [ERROR]: An error occurred: connection already closed
2023-09-15 10:52:30 [ERROR]: An error occurred: connection already closed
2023-09-15 10:52:32 [ERROR]: An error occurred: connection already closed
2023-09-15 10:52:34 [ERROR]: An error occurred: connection already closed
2023-09-15 10:52:36 [ERROR]: An error occurred: connection already closed
2023-09-15 10:52:38 [ERROR]: An error occurred: connection already closed
2023-09-15 10:52:40 [ERROR]: An error occurred: connection already closed
2023-09-15 10:52:44 [ERROR]: An error occurred: connection already closed
2023-09-15 10:52:46 [ERROR]: An error occurred: connection already closed
2023-09-15 10:52:48 [ERROR]: An error occurred: connection already closed
2023-09-15 10:52:50 [ERROR]: An error occurred: connection already closed
2023-09-15 10:52:52 [ERROR]: An error occurred: connection already closed
2023-09-15 10:52:54 [ERROR]: An error occurred: connection already closed
2023-09-15 10:52:56 [ERROR]: An error occurred: connection already closed
2023-09-15 10:52:58 [ERROR]: An error occurred: connection already closed
2023-09-15 10:53:00 [ERROR]: An error occurred: connection already closed
2023-09-15 10:53:01 [ERROR]: An error occurred: connection already closed
2023-09-15 10:53:04 [ERROR]: An error occurred: connection already closed
2023-09-15 10:53:06 [ERROR]: An error occurred: connection already closed
2023-09-15 10:53:08 [ERROR]: An error occurred: connection already closed
2023-09-15 10:53:09 [ERROR]: An error occurred: connection already closed
2023-09-15 10:53:12 [ERROR]: An error occurred: connection already closed
2023-09-15 10:53:14 [ERROR]: An error occurred: connection already closed
2023-09-15 10:53:16 [ERROR]: An error occurred: connection already closed
2023-09-15 10:53:18 [ERROR]: An error occurred: connection already closed
2023-09-15 10:53:20 [ERROR]: An error occurred: connection already closed
2023-09-15 10:53:22 [ERROR]: An error occurred: connection already closed
2023-09-15 10:53:24 [ERROR]: An error occurred: connection already closed
2023-09-15 10:53:26 [ERROR]: An error occurred: connection already closed
2023-09-15 10:53:28 [ERROR]: An error occurred: connection already closed
2023-09-15 10:53:30 [ERROR]: An error occurred: connection already closed
2023-09-15 10:53:38 [ERROR]: An error occurred: connection already closed
2023-09-15 10:53:38 [ERROR]: An error occurred: connection already closed
2023-09-15 10:53:40 [ERROR]: An error occurred: connection already closed
2023-09-15 10:53:42 [ERROR]: An error occurred: connection already closed
2023-09-15 10:53:44 [ERROR]: An error occurred: connection already closed
2023-09-15 10:53:46 [ERROR]: An error occurred: connection already closed
2023-09-15 10:53:48 [ERROR]: An error occurred: connection already closed
2023-09-15 10:53:50 [ERROR]: An error occurred: connection already closed
2023-09-15 10:53:52 [ERROR]: An error occurred: connection already closed
2023-09-15 10:53:54 [ERROR]: An error occurred: connection already closed
2023-09-15 10:53:56 [ERROR]: An error occurred: connection already closed
2023-09-15 10:53:58 [ERROR]: An error occurred: connection already closed
2023-09-15 10:54:00 [ERROR]: An error occurred: connection already closed
2023-09-15 10:54:02 [ERROR]: An error occurred: connection already closed
2023-09-15 10:54:04 [ERROR]: An error occurred: connection already closed
2023-09-15 10:54:06 [ERROR]: An error occurred: connection already closed
2023-09-15 10:54:08 [ERROR]: An error occurred: connection already closed
2023-09-15 10:54:10 [ERROR]: An error occurred: connection already closed
2023-09-15 10:54:12 [ERROR]: An error occurred: connection already closed
2023-09-15 10:54:14 [ERROR]: An error occurred: connection already closed
2023-09-15 10:54:16 [ERROR]: An error occurred: connection already closed
2023-09-15 10:54:17 [ERROR]: An error occurred: connection already closed
2023-09-15 10:54:20 [ERROR]: An error occurred: connection already closed
2023-09-15 10:54:21 [ERROR]: An error occurred: connection already closed
2023-09-15 10:54:24 [ERROR]: An error occurred: connection already closed
2023-09-15 10:54:26 [ERROR]: An error occurred: connection already closed
2023-09-15 10:54:28 [ERROR]: An error occurred: connection already closed
2023-09-15 10:54:29 [ERROR]: An error occurred: connection already closed
2023-09-15 10:54:32 [ERROR]: An error occurred: connection already closed
2023-09-15 10:54:34 [ERROR]: An error occurred: connection already closed
2023-09-15 10:54:36 [ERROR]: An error occurred: connection already closed
2023-09-15 10:54:38 [ERROR]: An error occurred: connection already closed
2023-09-15 11:14:54 [ERROR]: An error occurred: connection already closed
2023-09-15 11:14:56 [ERROR]: An error occurred: connection already closed
2023-09-15 11:14:58 [ERROR]: An error occurred: connection already closed
2023-09-15 11:15:00 [ERROR]: An error occurred: connection already closed
2023-09-15 11:15:02 [ERROR]: An error occurred: connection already closed
2023-09-15 11:15:04 [ERROR]: An error occurred: connection already closed
2023-09-15 11:15:06 [ERROR]: An error occurred: connection already closed
2023-09-15 11:15:08 [ERROR]: An error occurred: connection already closed
2023-09-15 11:15:10 [ERROR]: An error occurred: connection already closed
2023-09-15 11:15:12 [ERROR]: An error occurred: connection already closed
2023-09-15 11:15:14 [ERROR]: An error occurred: connection already closed
2023-09-15 11:15:16 [ERROR]: An error occurred: connection already closed
2023-09-15 11:15:18 [ERROR]: An error occurred: connection already closed
2023-09-15 11:15:20 [ERROR]: An error occurred: connection already closed
2023-09-15 11:15:22 [ERROR]: An error occurred: connection already closed
2023-09-15 11:15:23 [ERROR]: An error occurred: connection already closed
2023-09-15 11:15:26 [ERROR]: An error occurred: connection already closed
2023-09-15 11:15:28 [ERROR]: An error occurred: connection already closed
2023-09-16 02:57:47 [ERROR]: An error occurred: connection already closed
2023-09-16 02:57:51 [ERROR]: An error occurred: connection already closed
2023-09-16 02:57:55 [ERROR]: An error occurred: connection already closed
2023-09-16 02:58:00 [ERROR]: An error occurred: connection already closed
2023-09-16 02:58:01 [ERROR]: An error occurred: connection already closed
2023-09-16 02:58:05 [ERROR]: An error occurred: connection already closed
2023-09-16 02:58:31 [ERROR]: An error occurred: connection already closed
2023-09-16 02:58:33 [ERROR]: An error occurred: connection already closed
2023-09-16 02:58:39 [ERROR]: An error occurred: connection already closed
2023-09-16 02:58:46 [ERROR]: An error occurred: connection already closed
2023-09-16 02:58:56 [ERROR]: An error occurred: connection already closed
2023-09-16 02:58:58 [ERROR]: An error occurred: connection already closed
2023-09-16 02:58:59 [ERROR]: An error occurred: connection already closed
2023-09-16 02:59:07 [ERROR]: An error occurred: connection already closed
2023-09-16 02:59:10 [ERROR]: An error occurred: connection already closed
2023-09-16 02:59:13 [ERROR]: An error occurred: connection already closed
2023-09-16 02:59:16 [ERROR]: An error occurred: connection already closed
2023-09-16 02:59:18 [ERROR]: An error occurred: connection already closed
2023-09-16 02:59:20 [ERROR]: An error occurred: connection already closed
2023-09-16 02:59:22 [ERROR]: An error occurred: connection already closed
2023-09-16 02:59:24 [ERROR]: An error occurred: connection already closed
2023-09-16 03:00:19 [ERROR]: An error occurred: connection already closed
2023-09-16 03:00:22 [ERROR]: An error occurred: connection already closed
2023-09-16 03:00:28 [ERROR]: An error occurred: connection already closed
2023-09-16 19:11:54 [ERROR]: An error occurred: connection already closed
2023-09-17 06:53:50 [ERROR]: An error occurred: connection already closed
2023-09-17 06:53:52 [ERROR]: An error occurred: connection already closed
2023-09-17 06:53:53 [ERROR]: An error occurred: connection already closed
2023-09-17 06:53:57 [ERROR]: An error occurred: connection already closed
2023-09-17 06:53:57 [ERROR]: An error occurred: connection already closed
2023-09-17 06:53:59 [ERROR]: An error occurred: connection already closed
2023-09-17 06:54:02 [ERROR]: An error occurred: connection already closed
2023-09-17 06:54:07 [ERROR]: An error occurred: connection already closed
2023-09-17 06:54:11 [ERROR]: An error occurred: connection already closed
2023-09-17 06:54:14 [ERROR]: An error occurred: connection already closed
2023-09-17 06:54:18 [ERROR]: An error occurred: connection already closed
2023-09-17 06:54:31 [ERROR]: An error occurred: connection already closed
2023-09-17 06:54:32 [ERROR]: An error occurred: connection already closed
2023-09-17 06:54:35 [ERROR]: An error occurred: connection already closed
2023-09-17 06:54:41 [ERROR]: An error occurred: connection already closed
2023-09-17 06:54:49 [ERROR]: An error occurred: connection already closed
2023-09-17 06:54:51 [ERROR]: An error occurred: connection already closed
2023-09-17 06:54:52 [ERROR]: An error occurred: connection already closed
2023-09-17 06:54:57 [ERROR]: An error occurred: connection already closed
2023-09-17 06:55:03 [ERROR]: An error occurred: connection already closed
2023-09-17 06:55:08 [ERROR]: An error occurred: connection already closed
2023-09-17 06:55:12 [ERROR]: An error occurred: connection already closed
2023-09-17 06:55:14 [ERROR]: An error occurred: connection already closed
2023-09-17 06:55:15 [ERROR]: An error occurred: connection already closed
2023-09-17 06:55:18 [ERROR]: An error occurred: connection already closed
2023-09-17 06:55:19 [ERROR]: An error occurred: connection already closed
2023-09-17 06:55:21 [ERROR]: An error occurred: connection already closed
2023-09-17 06:55:25 [ERROR]: An error occurred: connection already closed
2023-09-17 06:55:31 [ERROR]: An error occurred: connection already closed
2023-09-17 06:55:34 [ERROR]: An error occurred: connection already closed
2023-09-17 06:55:38 [ERROR]: An error occurred: connection already closed
2023-09-17 06:55:41 [ERROR]: An error occurred: connection already closed
2023-09-17 06:55:43 [ERROR]: An error occurred: connection already closed
2023-09-17 06:55:47 [ERROR]: An error occurred: connection already closed
2023-09-17 06:55:48 [ERROR]: An error occurred: connection already closed
2023-09-17 14:51:44 [ERROR]: An error occurred: current transaction is aborted, commands ignored until end of transaction block

2023-09-17 14:52:06 [ERROR]: An error occurred: current transaction is aborted, commands ignored until end of transaction block

